<?xml version="1.0" ?>
<!-- =================================================================================== -->
<!-- |    This document was autogenerated by xacro from restorebot.urdf.xacro          | -->
<!-- |    EDITING THIS FILE BY HAND IS NOT RECOMMENDED                                 | -->
<!-- =================================================================================== -->
<robot name="restorebot" xmlns:xacro="http://ros.org/wiki/xacro">
  <material name="blue">
    <color rgba="0 0 0.8 1"/>
  </material>
  <material name="black">
    <color rgba="0 0 0 1"/>
  </material>
  <material name="white">
    <color rgba="1 1 1 1"/>
  </material>
  <link name="platform_base">
    <visual>
      <geometry>
        <box size="2 2 1"/>
      </geometry>
    </visual>
    <collision>
      <geometry>
        <box size="2 2 1"/>
      </geometry>
    </collision>
    <inertial>
      <mass value="10848.0"/>
      <inertia ixx="1.0" ixy="0.0" ixz="0.0" iyy="1.0" iyz="0.0" izz="1.0"/>
    </inertial>
  </link>
  <link name="armLink1">
    <visual>
      <geometry>
        <cylinder length="0.2" radius="0.2"/>
      </geometry>
      <origin rpy="0 0 0" xyz="0 0 0.1"/>
    </visual>
    <collision>
      <geometry>
        <cylinder length="0.2" radius="0.2"/>
      </geometry>
      <origin rpy="0 0 0" xyz="0 0 0.1"/>
    </collision>
    <inertial>
      <mass value="340.6272"/>
      <inertia ixx="1.0" ixy="0.0" ixz="0.0" iyy="1.0" iyz="0.0" izz="1.0"/>
    </inertial>
  </link>
  <joint name="base_to_link1" type="continuous">
    <parent link="platform_base"/>
    <child link="armLink1"/>
    <origin rpy="0 0 0" xyz="0 0 0.5"/>
    <axis xyz="0 0 1"/>
  </joint>
  <link name="armLink1square">
    <visual>
      <geometry>
        <box size="0.2 0.2 0.2"/>
      </geometry>
      <origin rpy="0 0 0" xyz="0 0 0.1"/>
    </visual>
    <collision>
      <geometry>
        <box size="0.2 0.2 0.2"/>
      </geometry>
      <origin rpy="0 0 0" xyz="0 0 0.1"/>
    </collision>
    <inertial>
      <mass value="542.4"/>
      <inertia ixx="1.0" ixy="0.0" ixz="0.0" iyy="1.0" iyz="0.0" izz="1.0"/>
    </inertial>
  </link>
  <joint name="armLink1Fixed" type="fixed">
    <parent link="armLink1"/>
    <child link="armLink1square"/>
    <origin rpy="0 0 0" xyz="0 0 0.2"/>
  </joint>
  <link name="armLink2">
    <visual>
      <geometry>
        <box size="0.2 0.2 0.2"/>
      </geometry>
      <origin rpy="0 0 0" xyz="0 0 0"/>
    </visual>
    <collision>
      <geometry>
        <box size="0.2 0.2 0.2"/>
      </geometry>
      <origin rpy="0 0 0" xyz="0 0 0"/>
    </collision>
    <inertial>
      <mass value="542.4"/>
      <inertia ixx="1.0" ixy="0.0" ixz="0.0" iyy="1.0" iyz="0.0" izz="1.0"/>
    </inertial>
  </link>
  <joint name="armLink1_to_armLink2" type="continuous">
    <parent link="armLink1square"/>
    <child link="armLink2"/>
    <origin rpy="0 0 0" xyz="0.2 0 0.1"/>
    <axis xyz="1 0 0"/>
  </joint>
  <link name="armLink3">
    <visual>
      <geometry>
        <cylinder length="0.8" radius="0.2"/>
      </geometry>
      <origin rpy="0 0 0" xyz="0 0 0.4"/>
    </visual>
    <collision>
      <geometry>
        <cylinder length="0.8" radius="0.2"/>
      </geometry>
      <origin rpy="0 0 0" xyz="0 0 0.4"/>
    </collision>
    <inertial>
      <mass value="1362.5088"/>
      <inertia ixx="1.0" ixy="0.0" ixz="0.0" iyy="1.0" iyz="0.0" izz="1.0"/>
    </inertial>
  </link>
  <joint name="armLink2_to_armLink3" type="continuous">
    <parent link="armLink2"/>
    <child link="armLink3"/>
    <origin rpy="0 0 0" xyz="0 0 0.1"/>
    <axis xyz="0 0 1"/>
  </joint>
  <link name="armLink3square">
    <visual>
      <geometry>
        <box size="0.2 0.2 0.2"/>
      </geometry>
      <origin rpy="0 0 0" xyz="0 0 0.1"/>
    </visual>
    <collision>
      <geometry>
        <box size="0.2 0.2 0.2"/>
      </geometry>
      <origin rpy="0 0 0" xyz="0 0 0.1"/>
    </collision>
    <inertial>
      <mass value="542.4"/>
      <inertia ixx="1.0" ixy="0.0" ixz="0.0" iyy="1.0" iyz="0.0" izz="1.0"/>
    </inertial>
  </link>
  <joint name="armLink3Fixed" type="fixed">
    <parent link="armLink3"/>
    <child link="armLink3square"/>
    <origin rpy="0 0 0" xyz="0 0 0.8"/>
  </joint>
  <link name="armLink4">
    <visual>
      <geometry>
        <box size="0.2 0.2 0.2"/>
      </geometry>
      <origin rpy="0 0 0" xyz="0 0 0"/>
    </visual>
    <collision>
      <geometry>
        <box size="0.2 0.2 0.2"/>
      </geometry>
      <origin rpy="0 0 0" xyz="0 0 0"/>
    </collision>
    <inertial>
      <mass value="542.4"/>
      <inertia ixx="1.0" ixy="0.0" ixz="0.0" iyy="1.0" iyz="0.0" izz="1.0"/>
    </inertial>
  </link>
  <joint name="armLink3_to_armLink4" type="continuous">
    <parent link="armLink3square"/>
    <child link="armLink4"/>
    <origin rpy="0 0 0" xyz="0.2 0 0.1"/>
    <axis xyz="1 0 0"/>
  </joint>
  <link name="armLink5">
    <visual>
      <geometry>
        <cylinder length="0.8" radius="0.2"/>
      </geometry>
      <origin rpy="0 0 0" xyz="0 0 0.4"/>
    </visual>
    <collision>
      <geometry>
        <cylinder length="0.8" radius="0.2"/>
      </geometry>
      <origin rpy="0 0 0" xyz="0 0 0.4"/>
    </collision>
    <inertial>
      <mass value="1362.5088"/>
      <inertia ixx="1.0" ixy="0.0" ixz="0.0" iyy="1.0" iyz="0.0" izz="1.0"/>
    </inertial>
  </link>
  <joint name="armLink4_to_armLink5" type="continuous">
    <parent link="armLink4"/>
    <child link="armLink5"/>
    <origin rpy="0 0 0" xyz="0 0 0.1"/>
    <axis xyz="0 0 1"/>
  </joint>
  <link name="armLink5square">
    <visual>
      <geometry>
        <box size="0.2 0.2 0.2"/>
      </geometry>
      <origin rpy="0 0 0" xyz="0 0 0.1"/>
    </visual>
    <collision>
      <geometry>
        <box size="0.2 0.2 0.2"/>
      </geometry>
      <origin rpy="0 0 0" xyz="0 0 0.1"/>
    </collision>
    <inertial>
      <mass value="542.4"/>
      <inertia ixx="1.0" ixy="0.0" ixz="0.0" iyy="1.0" iyz="0.0" izz="1.0"/>
    </inertial>
  </link>
  <joint name="armLink5Fixed" type="fixed">
    <parent link="armLink5"/>
    <child link="armLink5square"/>
    <origin rpy="0 0 0" xyz="0 0 0.8"/>
  </joint>
  <link name="armLink6">
    <visual>
      <geometry>
        <box size="0.2 0.2 0.2"/>
      </geometry>
      <origin rpy="0 0 0" xyz="0 0 0"/>
    </visual>
    <collision>
      <geometry>
        <box size="0.2 0.2 0.2"/>
      </geometry>
      <origin rpy="0 0 0" xyz="0 0 0"/>
    </collision>
    <inertial>
      <mass value="542.4"/>
      <inertia ixx="1.0" ixy="0.0" ixz="0.0" iyy="1.0" iyz="0.0" izz="1.0"/>
    </inertial>
  </link>
  <joint name="armLink5_to_armLink6" type="continuous">
    <parent link="armLink5square"/>
    <child link="armLink6"/>
    <origin rpy="0 0 0" xyz="-0.2 0 0.1"/>
    <axis xyz="1 0 0"/>
  </joint>
  <link name="armLink7">
    <visual>
      <geometry>
        <cylinder length="0.2" radius="0.2"/>
      </geometry>
      <origin rpy="0 0 0" xyz="0 0 0.1"/>
    </visual>
    <collision>
      <geometry>
        <cylinder length="0.2" radius="0.2"/>
      </geometry>
      <origin rpy="0 0 0" xyz="0 0 0.1"/>
    </collision>
    <inertial>
      <mass value="340.6272"/>
      <inertia ixx="1.0" ixy="0.0" ixz="0.0" iyy="1.0" iyz="0.0" izz="1.0"/>
    </inertial>
  </link>
  <joint name="armLink6_to_armLink7" type="continuous">
    <parent link="armLink6"/>
    <child link="armLink7"/>
    <origin rpy="0 0 0" xyz="0 0 0.1"/>
    <axis xyz="0 0 1"/>
  </joint>
  <link name="armLink7square">
    <visual>
      <geometry>
        <box size="0.2 0.2 0.2"/>
      </geometry>
      <origin rpy="0 0 0" xyz="0 0 0.1"/>
    </visual>
    <collision>
      <geometry>
        <box size="0.2 0.2 0.2"/>
      </geometry>
      <origin rpy="0 0 0" xyz="0 0 0.1"/>
    </collision>
    <inertial>
      <mass value="542.4"/>
      <inertia ixx="1.0" ixy="0.0" ixz="0.0" iyy="1.0" iyz="0.0" izz="1.0"/>
    </inertial>
  </link>
  <joint name="armLink7Fixed" type="fixed">
    <parent link="armLink7"/>
    <child link="armLink7square"/>
    <origin rpy="0 0 0" xyz="0 0 0.2"/>
  </joint>
</robot>

