<?xml version="1.0" ?>
<!-- =================================================================================== -->
<!-- |    This document was autogenerated by xacro from restorebot.urdf.xacro          | -->
<!-- |    EDITING THIS FILE BY HAND IS NOT RECOMMENDED                                 | -->
<!-- =================================================================================== -->
<robot name="restorebot" xmlns:xacro="http://ros.org/wiki/xacro">
  <material name="blue">
    <color rgba="0 0 0.8 1"/>
  </material>
  <material name="black">
    <color rgba="0 .2 0 1"/>
  </material>
  <material name="white">
    <color rgba="1 1 1 1"/>
  </material>
  <material name="cyan">
    <color rgba="0 1 1 1"/>
  </material>
  <!--	****************
			****************
			****************

			Base Platform

			****************
			****************
			****************
	-->
  <link name="platform_base">
    <visual>
      <geometry>
        <box size="8 8 1"/>
      </geometry>
      <material name="black"/>
    </visual>
    <collision>
      <geometry>
        <box size="8 8 1"/>
      </geometry>
    </collision>
    <inertial>
      <mass value="173568"/>
      <inertia ixx="5.41666666667" ixy="0.0" ixz="0.0" iyy="5.41666666667" iyz="0.0" izz="10.6666666667"/>
    </inertial>
  </link>
  <!--	****************
			****************
			****************

 				Arm Link 1

			****************
			****************
			****************
	-->
  <link name="armLink1">
    <visual>
      <geometry>
        <cylinder length="0.4" radius="0.2"/>
      </geometry>
      <origin rpy="0 0 0" xyz="0 0 0.2"/>
      <material name="white"/>
    </visual>
    <collision>
      <geometry>
        <cylinder length="0.4" radius="0.2"/>
      </geometry>
      <origin rpy="0 0 0" xyz="0 0 0.2"/>
    </collision>
    <inertial>
      <mass value="136.25088"/>
      <inertia ixx="0.0633333333333" ixy="0.0" ixz="0.0" iyy="0.0633333333333" iyz="0.0" izz="0.02"/>
    </inertial>
  </link>
  <joint name="base_to_link1" type="continuous">
    <parent link="platform_base"/>
    <child link="armLink1"/>
    <origin rpy="0 0 0" xyz="2.0 2.0 0.5"/>
    <axis xyz="0 0 1"/>
  </joint>
  <link name="armLink1square">
    <visual>
      <geometry>
        <box size="0.44 0.44 0.44"/>
      </geometry>
      <origin rpy="0 0 0" xyz="0 0 0.22"/>
      <material name="white"/>
    </visual>
    <collision>
      <geometry>
        <box size="0.44 0.44 0.44"/>
      </geometry>
      <origin rpy="0 0 0" xyz="0 0 0.22"/>
    </collision>
    <inertial>
      <mass value="231.019008"/>
      <inertia ixx="0.0806666666667" ixy="0.0" ixz="0.0" iyy="0.0806666666667" iyz="0.0" izz="0.0322666666667"/>
    </inertial>
  </link>
  	
s
	
  <joint name="armLink1Fixed" type="fixed">
    <parent link="armLink1"/>
    <child link="armLink1square"/>
    <origin rpy="0 0 0" xyz="0 0 0.4"/>
  </joint>
  <!--	****************
			****************
			****************

 				Arm Link 2

			****************
			****************
			****************
	-->
  <link name="armLink2">
    <visual>
      <geometry>
        <box size="0.44 0.44 0.44"/>
      </geometry>
      <origin rpy="0 0 0" xyz="0 0 0"/>
      <material name="blue"/>
    </visual>
    <collision>
      <geometry>
        <box size="0.44 0.44 0.44"/>
      </geometry>
      <origin rpy="0 0 0" xyz="0 0 0"/>
    </collision>
    <inertial>
      <mass value="231.019008"/>
      <inertia ixx="0.0322666666667" ixy="0.0" ixz="0.0" iyy="0.0322666666667" iyz="0.0" izz="0.0322666666667"/>
    </inertial>
  </link>
  <joint name="armLink1_to_armLink2" type="continuous">
    <parent link="armLink1square"/>
    <child link="armLink2"/>
    <origin rpy="0 0 0" xyz="0.44 0 0.22"/>
    <axis xyz="1 0 0"/>
  </joint>
  <!--	****************
			****************
			****************

 				Arm Link 3

			****************
			****************
			****************
	-->
  <link name="armLink3">
    <visual>
      <geometry>
        <cylinder length="0.8" radius="0.2"/>
      </geometry>
      <origin rpy="0 0 0" xyz="0 0 0.4"/>
      <material name="white"/>
    </visual>
    <collision>
      <geometry>
        <cylinder length="0.8" radius="0.2"/>
      </geometry>
      <origin rpy="0 0 0" xyz="0 0 0.4"/>
    </collision>
    <inertial>
      <mass value="272.50176"/>
      <inertia ixx="0.223333333333" ixy="0.0" ixz="0.0" iyy="0.223333333333" iyz="0.0" izz="0.02"/>
    </inertial>
  </link>
  <joint name="armLink2_to_armLink3" type="continuous">
    <parent link="armLink2"/>
    <child link="armLink3"/>
    <origin rpy="0 0 0" xyz="0 0 0.22"/>
    <axis xyz="0 0 1"/>
  </joint>
  <link name="armLink3square">
    <visual>
      <geometry>
        <box size="0.44 0.44 0.44"/>
      </geometry>
      <origin rpy="0 0 0" xyz="0 0 0.22"/>
      <material name="white"/>
    </visual>
    <collision>
      <geometry>
        <box size="0.44 0.44 0.44"/>
      </geometry>
      <origin rpy="0 0 0" xyz="0 0 0.22"/>
    </collision>
    <inertial>
      <mass value="231.019008"/>
      <inertia ixx="0.0806666666667" ixy="0.0" ixz="0.0" iyy="0.0806666666667" iyz="0.0" izz="0.0322666666667"/>
    </inertial>
  </link>
  <joint name="armLink3Fixed" type="fixed">
    <parent link="armLink3"/>
    <child link="armLink3square"/>
    <origin rpy="0 0 0" xyz="0 0 0.8"/>
  </joint>
  <!--	****************
			****************
			****************

 				Arm Link 4

			****************
			****************
			****************
	-->
  <link name="armLink4">
    <visual>
      <geometry>
        <box size="0.44 0.44 0.44"/>
      </geometry>
      <origin rpy="0 0 0" xyz="0 0 0"/>
      <material name="blue"/>
    </visual>
    <collision>
      <geometry>
        <box size="0.44 0.44 0.44"/>
      </geometry>
      <origin rpy="0 0 0" xyz="0 0 0"/>
    </collision>
    <inertial>
      <mass value="231.019008"/>
      <inertia ixx="0.0322666666667" ixy="0.0" ixz="0.0" iyy="0.0322666666667" iyz="0.0" izz="0.0322666666667"/>
    </inertial>
  </link>
  <joint name="armLink3_to_armLink4" type="continuous">
    <parent link="armLink3square"/>
    <child link="armLink4"/>
    <origin rpy="0 0 0" xyz="0.44 0 0.22"/>
    <axis xyz="1 0 0"/>
  </joint>
  <!--	****************
			****************
			****************

 				Arm Link 5

			****************
			****************
			****************
	-->
  <link name="armLink5">
    <visual>
      <geometry>
        <cylinder length="0.8" radius="0.2"/>
      </geometry>
      <origin rpy="0 0 0" xyz="0 0 0.4"/>
      <material name="white"/>
    </visual>
    <collision>
      <geometry>
        <cylinder length="0.8" radius="0.2"/>
      </geometry>
      <origin rpy="0 0 0" xyz="0 0 0.4"/>
    </collision>
    <inertial>
      <mass value="272.50176"/>
      <inertia ixx="0.223333333333" ixy="0.0" ixz="0.0" iyy="0.223333333333" iyz="0.0" izz="0.02"/>
    </inertial>
  </link>
  <joint name="armLink4_to_armLink5" type="continuous">
    <parent link="armLink4"/>
    <child link="armLink5"/>
    <origin rpy="0 0 0" xyz="0 0 0.22"/>
    <axis xyz="0 0 1"/>
  </joint>
  <link name="armLink5square">
    <visual>
      <geometry>
        <box size="0.44 0.44 0.44"/>
      </geometry>
      <origin rpy="0 0 0" xyz="0 0 0.22"/>
      <material name="white"/>
    </visual>
    <collision>
      <geometry>
        <box size="0.44 0.44 0.44"/>
      </geometry>
      <origin rpy="0 0 0" xyz="0 0 0.22"/>
    </collision>
    <inertial>
      <mass value="231.019008"/>
      <inertia ixx="0.0806666666667" ixy="0.0" ixz="0.0" iyy="0.0806666666667" iyz="0.0" izz="0.0322666666667"/>
    </inertial>
  </link>
  <joint name="armLink5Fixed" type="fixed">
    <parent link="armLink5"/>
    <child link="armLink5square"/>
    <origin rpy="0 0 0" xyz="0 0 0.8"/>
  </joint>
  <!--	****************
			****************
			****************

 				Arm Link 6

			****************
			****************
			****************
	-->
  <link name="armLink6">
    <visual>
      <geometry>
        <box size="0.44 0.44 0.44"/>
      </geometry>
      <origin rpy="0 0 0" xyz="0 0 0"/>
      <material name="blue"/>
    </visual>
    <collision>
      <geometry>
        <box size="0.44 0.44 0.44"/>
      </geometry>
      <origin rpy="0 0 0" xyz="0 0 0"/>
    </collision>
    <inertial>
      <mass value="231.019008"/>
      <inertia ixx="0.0322666666667" ixy="0.0" ixz="0.0" iyy="0.0322666666667" iyz="0.0" izz="0.0322666666667"/>
    </inertial>
  </link>
  <joint name="armLink5_to_armLink6" type="continuous">
    <parent link="armLink5square"/>
    <child link="armLink6"/>
    <origin rpy="0 0 0" xyz="-0.44 0 0.22"/>
    <axis xyz="1 0 0"/>
  </joint>
  <!--	****************
			****************
			****************

 				Arm Link 7

			****************
			****************
			****************
	-->
  <link name="armLink7">
    <visual>
      <geometry>
        <cylinder length="0.4" radius="0.2"/>
      </geometry>
      <origin rpy="0 0 0" xyz="0 0 0.2"/>
      <material name="white"/>
    </visual>
    <collision>
      <geometry>
        <cylinder length="0.4" radius="0.2"/>
      </geometry>
      <origin rpy="0 0 0" xyz="0 0 0.2"/>
    </collision>
    <inertial>
      <mass value="136.25088"/>
      <inertia ixx="0.0633333333333" ixy="0.0" ixz="0.0" iyy="0.0633333333333" iyz="0.0" izz="0.02"/>
    </inertial>
  </link>
  <joint name="armLink6_to_armLink7" type="continuous">
    <parent link="armLink6"/>
    <child link="armLink7"/>
    <origin rpy="0 0 0" xyz="0 0 0.22"/>
    <axis xyz="0 0 1"/>
  </joint>
  <link name="armLink7square">
    <visual>
      <geometry>
        <box size="0.2 0.2 0.2"/>
      </geometry>
      <origin rpy="0 0 0" xyz="0 0 0.1"/>
      <material name="white"/>
    </visual>
    <collision>
      <geometry>
        <box size="0.2 0.2 0.2"/>
      </geometry>
      <origin rpy="0 0 0" xyz="0 0 0.1"/>
    </collision>
    <inertial>
      <mass value="21.696"/>
      <inertia ixx="0.0166666666667" ixy="0.0" ixz="0.0" iyy="0.0166666666667" iyz="0.0" izz="0.00666666666667"/>
    </inertial>
  </link>
  <joint name="armLink7Fixed" type="fixed">
    <parent link="armLink7"/>
    <child link="armLink7square"/>
    <origin rpy="0 0 0" xyz="0 0 0.4"/>
  </joint>
  <!--	****************
			****************
			****************

 Beginning of the Satellite/Support Section

			****************
			****************
			****************
	-->
  <link name="support1">
    <visual>
      <geometry>
        <cylinder length="1.5" radius="0.2"/>
      </geometry>
      <origin rpy="0 0 0" xyz="0 0 0.75"/>
      <material name="black"/>
    </visual>
    <collision>
      <geometry>
        <cylinder length="1.5" radius="0.2"/>
      </geometry>
      <origin rpy="0 0 0" xyz="0 0 0.75"/>
    </collision>
    <inertial>
      <mass value="510.9408"/>
      <inertia ixx="0.76" ixy="0.0" ixz="0.0" iyy="0.76" iyz="0.0" izz="0.02"/>
    </inertial>
  </link>
  <joint name="base_to_sup1" type="fixed">
    <parent link="platform_base"/>
    <child link="support1"/>
    <origin rpy="0 0 0" xyz="-2.0 -1 0.5"/>
  </joint>
  <link name="support2">
    <visual>
      <geometry>
        <cylinder length="1.5" radius="0.2"/>
      </geometry>
      <origin rpy="0 0 0" xyz="0 0 0.75"/>
      <material name="black"/>
    </visual>
    <collision>
      <geometry>
        <cylinder length="1.5" radius="0.2"/>
      </geometry>
      <origin rpy="0 0 0" xyz="0 0 0.75"/>
    </collision>
    <inertial>
      <mass value="510.9408"/>
      <inertia ixx="0.76" ixy="0.0" ixz="0.0" iyy="0.76" iyz="0.0" izz="0.02"/>
    </inertial>
  </link>
  <joint name="base_to_sup2" type="fixed">
    <parent link="platform_base"/>
    <child link="support2"/>
    <origin rpy="0 0 0" xyz="-1.15 0.5 0.5"/>
  </joint>
  <link name="support3">
    <visual>
      <geometry>
        <cylinder length="1.5" radius="0.2"/>
      </geometry>
      <origin rpy="0 0 0" xyz="0 0 0.75"/>
      <material name="black"/>
    </visual>
    <collision>
      <geometry>
        <cylinder length="1.5" radius="0.2"/>
      </geometry>
      <origin rpy="0 0 0" xyz="0 0 0.75"/>
    </collision>
    <inertial>
      <mass value="510.9408"/>
      <inertia ixx="0.76" ixy="0.0" ixz="0.0" iyy="0.76" iyz="0.0" izz="0.02"/>
    </inertial>
  </link>
  <joint name="base_to_sup3" type="fixed">
    <parent link="platform_base"/>
    <child link="support3"/>
    <origin rpy="0 0 0" xyz="-2.85 0.5 0.5"/>
  </joint>
  <!--	****************
			****************
			****************

	 			Satellite

			****************
			****************
			****************
	-->
  <link name="satellite">
    <visual>
      <geometry>
        <box size="5 5 5"/>
      </geometry>
      <origin rpy="0 0 0" xyz="0 0 2.5"/>
      <material name="black"/>
    </visual>
    <collision>
      <geometry>
        <box size="5 5 5"/>
      </geometry>
      <origin rpy="0 0 0" xyz="0 0 2.5"/>
    </collision>
    <inertial>
      <mass value="339000"/>
      <inertia ixx="10.4166666667" ixy="0.0" ixz="0.0" iyy="10.4166666667" iyz="0.0" izz="2.08333333333"/>
    </inertial>
  </link>
  <joint name="sup1_to_satellite" type="fixed">
    <parent link="support1"/>
    <child link="satellite"/>
    <origin rpy="0 0 0" xyz="0 1 1.5"/>
  </joint>
  <!--	****************
			****************
			****************

	 		  Clutter

			****************
			****************
			****************
	-->
  <link name="clutter1">
    <visual>
      <geometry>
        <sphere radius="0.3"/>
      </geometry>
      <material name="cyan"/>
    </visual>
    <collision>
      <geometry>
        <sphere radius="0.3"/>
      </geometry>
    </collision>
    <inertial>
      <mass value="73.224"/>
      <inertia ixx="0.036" ixy="0.0" ixz="0.0" iyy="0.036" iyz="0.0" izz="0.036"/>
    </inertial>
  </link>
  <joint name="platform_to_clutter1" type="fixed">
    <parent link="platform_base"/>
    <child link="clutter1"/>
    <origin rpy="0 0 0" xyz="2 2 3"/>
  </joint>
  <link name="clutter2">
    <visual>
      <geometry>
        <sphere radius="0.2"/>
      </geometry>
      <material name="cyan"/>
    </visual>
    <collision>
      <geometry>
        <sphere radius="0.2"/>
      </geometry>
    </collision>
    <inertial>
      <mass value="21.696"/>
      <inertia ixx="0.016" ixy="0.0" ixz="0.0" iyy="0.016" iyz="0.0" izz="0.016"/>
    </inertial>
  </link>
  <joint name="platform_to_clutter2" type="fixed">
    <parent link="platform_base"/>
    <child link="clutter2"/>
    <origin rpy="0 0 0" xyz="1.5 0 2"/>
  </joint>
</robot>

